Workbook

Sheet Indications table
A1: Month and Year | B1: url Highlights | C1: New medicines | Extensions of indications | D1: Name of medicine | E1: International non-proprietary name (INN) | F1: Therapeutic area (MeSH) | G1: Pharmacotherapeutic group | H1: ATC code | I1: ATC code WHO | J1: ATC L01|L02 | K1: url EPAR | L1: Procedure No | M1: Recommended indication | N1: indications in (haemato)-oncology | O1: Extension of indication for pediatric population | P1: Indication included | Q1: Reason(s) for non-inclusion | R1: Number of main studies | S1: Study identifier | T1: NCT | U1: EudraCT
A2: 43831 | B2: https://www.ema.europa.eu/en/news/meeting-highlights-committee-medicinal-products-human-use-chmp-27-30-january-2020 | C2: New medicines | D2: Givlaari | E2: =IFERROR(IF(VLOOKUP($D2,'Medicine outputs'!$B:$AM,6,0)=0,"",VLOOKUP($D2,'Medicine outputs'!$B:$AM,6,0)),"") -> givosiran | F2: =IFERROR(IF(VLOOKUP($D2,'Medicine outputs'!$B:$AM,8,0)=0,"",VLOOKUP($D2,'Medicine outputs'!$B:$AM,8,0)),"") -> Porphyrias, Hepatic | G2: =IFERROR(IF(VLOOKUP($D2,'Medicine outputs'!$B:$AM,13,0)=0,"",VLOOKUP($D2,'Medicine outputs'!$B:$AM,13,0)),"") -> Various alimentary tract and metabolism products | H2: =IFERROR(IF(VLOOKUP($D2,'Medicine outputs'!$B:$AM,11,0)=0,"",VLOOKUP($D2,'Medicine outputs'!$B:$AM,11,0)),"") -> A16AX16 | I2: NA | J2: =IF(OR(LEFT(H2,3)="L01",LEFT(H2,3)="L02",LEFT(I2,3)="L01",LEFT(I2,3)="L02"),"Yes","No") -> No | K2: NA | L2: NA | M2: NA | N2: NA | O2: NA | P2: =IF(OR(J2="No",N2="No",O2="Yes",Q2<>"NA"),"No","Yes") -> No | Q2: ATC code other than L01|L02 | R2: NA | S2: NA | T2: NA | U2: NA
A3: 43831 | B3: https://www.ema.europa.eu/en/news/meeting-highlights-committee-medicinal-products-human-use-chmp-27-30-january-2020 | C3: New medicines | D3: Lyumjev (previously Liumjev) | E3: =IFERROR(IF(VLOOKUP($D3,'Medicine outputs'!$B:$AM,6,0)=0,"",VLOOKUP($D3,'Medicine outputs'!$B:$AM,6,0)),"") -> insulin lispro | F3: =IFERROR(IF(VLOOKUP($D3,'Medicine outputs'!$B:$AM,8,0)=0,"",VLOOKUP($D3,'Medicine outputs'!$B:$AM,8,0)),"") -> Diabetes Mellitus | G3: =IFERROR(IF(VLOOKUP($D3,'Medicine outputs'!$B:$AM,13,0)=0,"",VLOOKUP($D3,'Medicine outputs'!$B:$AM,13,0)),"") -> Drugs used in diabetes | H3: =IFERROR(IF(VLOOKUP($D3,'Medicine outputs'!$B:$AM,11,0)=0,"",VLOOKUP($D3,'Medicine outputs'!$B:$AM,11,0)),"") -> A10AB04 | I3: NA | J3: =IF(OR(LEFT(H3,3)="L01",LEFT(H3,3)="L02",LEFT(I3,3)="L01",LEFT(I3,3)="L02"),"Yes","No") -> No | K3: NA | L3: NA | M3: NA | N3: NA | O3: NA | P3: =IF(OR(J3="No",N3="No",O3="Yes",Q3<>"NA"),"No","Yes") -> No | Q3: ATC code other than L01|L02 | R3: NA | S3: NA | T3: NA | U3: NA
A4: 43831 | B4: https://www.ema.europa.eu/en/news/meeting-highlights-committee-medicinal-products-human-use-chmp-27-30-january-2020 | C4: New medicines | D4: Nilemdo | E4: =IFERROR(IF(VLOOKUP($D4,'Medicine outputs'!$B:$AM,6,0)=0,"",VLOOKUP($D4,'Medicine outputs'!$B:$AM,6,0)),"") -> bempedoic acid | F4: =IFERROR(IF(VLOOKUP($D4,'Medicine outputs'!$B:$AM,8,0)=0,"",VLOOKUP($D4,'Medicine outputs'!$B:$AM,8,0)),"") -> Hypercholesterolemia;Dyslipidemias | G4: =IFERROR(IF(VLOOKUP($D4,'Medicine outputs'!$B:$AM,13,0)=0,"",VLOOKUP($D4,'Medicine outputs'!$B:$AM,13,0)),"") -> Lipid modifying agents | H4: =IFERROR(IF(VLOOKUP($D4,'Medicine outputs'!$B:$AM,11,0)=0,"",VLOOKUP($D4,'Medicine outputs'!$B:$AM,11,0)),"") -> C10AX | I4: NA | J4: =IF(OR(LEFT(H4,3)="L01",LEFT(H4,3)="L02",LEFT(I4,3)="L01",LEFT(I4,3)="L02"),"Yes","No") -> No | K4: NA | L4: NA | M4: NA | N4: NA | O4: NA | P4: =IF(OR(J4="No",N4="No",O4="Yes",Q4<>"NA"),"No","Yes") -> No | Q4: ATC code other than L01|L02 | R4: NA | S4: NA | T4: NA | U4: NA
A5: 43831 | B5: https://www.ema.europa.eu/en/news/meeting-highlights-committee-medicinal-products-human-use-chmp-27-30-january-2020 | C5: New medicines | D5: Nubeqa | E5: =IFERROR(IF(VLOOKUP($D5,'Medicine outputs'!$B:$AM,6,0)=0,"",VLOOKUP($D5,'Medicine outputs'!$B:$AM,6,0)),"") -> darolutamide | F5: =IFERROR(IF(VLOOKUP($D5,'Medicine outputs'!$B:$AM,8,0)=0,"",VLOOKUP($D5,'Medicine outputs'!$B:$AM,8,0)),"") -> Prostatic Neoplasms, Castration-Resistant | G5: =IFERROR(IF(VLOOKUP($D5,'Medicine outputs'!$B:$AM,13,0)=0,"",VLOOKUP($D5,'Medicine outputs'!$B:$AM,13,0)),"") -> Endocrine therapy | H5: =IFERROR(IF(VLOOKUP($D5,'Medicine outputs'!$B:$AM,11,0)=0,"",VLOOKUP($D5,'Medicine outputs'!$B:$AM,11,0)),"") -> L02BB | I5: NA | J5: =IF(OR(LEFT(H5,3)="L01",LEFT(H5,3)="L02",LEFT(I5,3)="L01",LEFT(I5,3)="L02"),"Yes","No") -> Yes | K5: https://www.ema.europa.eu/en/documents/assessment-report/nubeqa-epar-public-assessment-report_en.pdf | L5: EMEA/H/C/004790/0000 | M5: NUBEQA is indicated for the treatment of adult men with non-metastatic castration resistant prostate cancer (nmCRPC) who are at high risk of developing metastatic disease. | N5: Yes | O5: No | P5: =IF(OR(J5="No",N5="No",O5="Yes",Q5<>"NA"),"No","Yes") -> Yes | Q5: NA | R5: 1 | S5: 17712 | T5: NCT02200614 | U5: 2013-003820-36
A6: 43831 | B6: https://www.ema.europa.eu/en/news/meeting-highlights-committee-medicinal-products-human-use-chmp-27-30-january-2020 | C6: New medicines | D6: Nustendi | E6: =IFERROR(IF(VLOOKUP($D6,'Medicine outputs'!$B:$AM,6,0)=0,"",VLOOKUP($D6,'Medicine outputs'!$B:$AM,6,0)),"") -> bempedoic acid;ezetimibe | F6: =IFERROR(IF(VLOOKUP($D6,'Medicine outputs'!$B:$AM,8,0)=0,"",VLOOKUP($D6,'Medicine outputs'!$B:$AM,8,0)),"") -> Hypercholesterolemia;Dyslipidemias | G6: =IFERROR(IF(VLOOKUP($D6,'Medicine outputs'!$B:$AM,13,0)=0,"",VLOOKUP($D6,'Medicine outputs'!$B:$AM,13,0)),"") -> Lipid modifying agents | H6: =IFERROR(IF(VLOOKUP($D6,'Medicine outputs'!$B:$AM,11,0)=0,"",VLOOKUP($D6,'Medicine outputs'!$B:$AM,11,0)),"") -> C10B | I6: NA | J6: =IF(OR(LEFT(H6,3)="L01",LEFT(H6,3)="L02",LEFT(I6,3)="L01",LEFT(I6,3)="L02"),"Yes","No") -> No | K6: NA | L6: NA | M6: NA | N6: NA | O6: NA | P6: =IF(OR(J6="No",N6="No",O6="Yes",Q6<>"NA"),"No","Yes") -> No | Q6: ATC code other than L01|L02 | R6: NA | S6: NA | T6: NA | U6: NA
A7: 43831 | B7: https://www.ema.europa.eu/en/news/meeting-highlights-committee-medicinal-products-human-use-chmp-27-30-january-2020 | C7: New medicines | D7: Rybelsus | E7: =IFERROR(IF(VLOOKUP($D7,'Medicine outputs'!$B:$AM,6,0)=0,"",VLOOKUP($D7,'Medicine outputs'!$B:$AM,6,0)),"") -> semaglutide | F7: =IFERROR(IF(VLOOKUP($D7,'Medicine outputs'!$B:$AM,8,0)=0,"",VLOOKUP($D7,'Medicine outputs'!$B:$AM,8,0)),"") -> Diabetes Mellitus, Type 2 | G7: =IFERROR(IF(VLOOKUP($D7,'Medicine outputs'!$B:$AM,13,0)=0,"",VLOOKUP($D7,'Medicine outputs'!$B:$AM,13,0)),"") -> Drugs used in diabetes | H7: =IFERROR(IF(VLOOKUP($D7,'Medicine outputs'!$B:$AM,11,0)=0,"",VLOOKUP($D7,'Medicine outputs'!$B:$AM,11,0)),"") -> A10BJ06 | I7: NA | J7: =IF(OR(LEFT(H7,3)="L01",LEFT(H7,3)="L02",LEFT(I7,3)="L01",LEFT(I7,3)="L02"),"Yes","No") -> No | K7: NA | L7: NA | M7: NA | N7: NA | O7: NA | P7: =IF(OR(J7="No",N7="No",O7="Yes",Q7<>"NA"),"No","Yes") -> No | Q7: ATC code other than L01|L02 | R7: NA | S7: NA | T7: NA | U7: NA
A8: 43831 | B8: https://www.ema.europa.eu/en/news/meeting-highlights-committee-medicinal-products-human-use-chmp-27-30-january-2020 | C8: New medicines | D8: Staquis | E8: =IFERROR(IF(VLOOKUP($D8,'Medicine outputs'!$B:$AM,6,0)=0,"",VLOOKUP($D8,'Medicine outputs'!$B:$AM,6,0)),"") -> crisaborole | F8: =IFERROR(IF(VLOOKUP($D8,'Medicine outputs'!$B:$AM,8,0)=0,"",VLOOKUP($D8,'Medicine outputs'!$B:$AM,8,0)),"") -> Dermatitis, Atopic | G8: =IFERROR(IF(VLOOKUP($D8,'Medicine outputs'!$B:$AM,13,0)=0,"",VLOOKUP($D8,'Medicine outputs'!$B:$AM,13,0)),"") -> Other dermatological preparations | H8: =IFERROR(IF(VLOOKUP($D8,'Medicine outputs'!$B:$AM,11,0)=0,"",VLOOKUP($D8,'Medicine outputs'!$B:$AM,11,0)),"") -> D11AH06 | I8: NA | J8: =IF(OR(LEFT(H8,3)="L01",LEFT(H8,3)="L02",LEFT(I8,3)="L01",LEFT(I8,3)="L02"),"Yes","No") -> No | K8: NA | L8: NA | M8: NA | N8: NA | O8: NA | P8: =IF(OR(J8="No",N8="No",O8="Yes",Q8<>"NA"),"No","Yes") -> No | Q8: ATC code other than L01|L02 | R8: NA | S8: NA | T8: NA | U8: NA
A9: 43831 | B9: https://www.ema.europa.eu/en/news/meeting-highlights-committee-medicinal-products-human-use-chmp-27-30-january-2020 | C9: New medicines | D9: Vaxchora | E9: =IFERROR(IF(VLOOKUP($D9,'Medicine outputs'!$B:$AM,6,0)=0,"",VLOOKUP($D9,'Medicine outputs'!$B:$AM,6,0)),"") -> cholera vaccine, oral, live | F9: =IFERROR(IF(VLOOKUP($D9,'Medicine outputs'!$B:$AM,8,0)=0,"",VLOOKUP($D9,'Medicine outputs'!$B:$AM,8,0)),"") -> Cholera | G9: =IFERROR(IF(VLOOKUP($D9,'Medicine outputs'!$B:$AM,13,0)=0,"",VLOOKUP($D9,'Medicine outputs'!$B:$AM,13,0)),"") -> Vaccines | H9: =IFERROR(IF(VLOOKUP($D9,'Medicine outputs'!$B:$AM,11,0)=0,"",VLOOKUP($D9,'Medicine outputs'!$B:$AM,11,0)),"") -> J07AE02 | I9: NA | J9: =IF(OR(LEFT(H9,3)="L01",LEFT(H9,3)="L02",LEFT(I9,3)="L01",LEFT(I9,3)="L02"),"Yes","No") -> No | K9: NA | L9: NA | M9: NA | N9: NA | O9: NA | P9: =IF(OR(J9="No",N9="No",O9="Yes",Q9<>"NA"),"No","Yes") -> No | Q9: ATC code other than L01|L02 | R9: NA | S9: NA | T9: NA | U9: NA
A10: 43831 | B10: https://www.ema.europa.eu/en/news/meeting-highlights-committee-medicinal-products-human-use-chmp-27-30-january-2020 | C10: Extensions of indications | D10: Ameluz | E10: =IFERROR(IF(VLOOKUP($D10,'Medicine outputs'!$B:$AM,6,0)=0,"",VLOOKUP($D10,'Medicine outputs'!$B:$AM,6,0)),"") -> 5-aminolevulinic acid hydrochloride | F10: =IFERROR(IF(VLOOKUP($D10,'Medicine outputs'!$B:$AM,8,0)=0,"",VLOOKUP($D10,'Medicine outputs'!$B:$AM,8,0)),"") -> Keratosis, Actinic;Carcinoma, Basal Cell | G10: =IFERROR(IF(VLOOKUP($D10,'Medicine outputs'!$B:$AM,13,0)=0,"",VLOOKUP($D10,'Medicine outputs'!$B:$AM,13,0)),"") -> Antineoplastic agents | H10: =IFERROR(IF(VLOOKUP($D10,'Medicine outputs'!$B:$AM,11,0)=0,"",VLOOKUP($D10,'Medicine outputs'!$B:$AM,11,0)),"") -> L01XD04 | I10: NA | J10: =IF(OR(LEFT(H10,3)="L01",LEFT(H10,3)="L02",LEFT(I10,3)="L01",LEFT(I10,3)="L02"),"Yes","No") -> Yes | K10: https://www.ema.europa.eu/en/documents/variation-report/ameluz-h-c-2204-ii-0039-g-epar-assessment-report-variation_en.pdf | L10: EMEA/H/C/002204/II/0039/G | M10: Extension of indication to include the treatment of mild to severe actinic keratosis on extremities, trunk and neck and of field cancerization in adults for Ameluz. | N10: No | O10: NA | P10: =IF(OR(J10="No",N10="No",O10="Yes",Q10<>"NA"),"No","Yes") -> No | Q10: Indications other than onco-hematology | R10: NA | S10: NA | T10: NA | U10: NA
A11: 43831 | B11: https://www.ema.europa.eu/en/news/meeting-highlights-committee-medicinal-products-human-use-chmp-27-30-january-2020 | C11: Extensions of indications | D11: MabThera | E11: =IFERROR(IF(VLOOKUP($D11,'Medicine outputs'!$B:$AM,6,0)=0,"",VLOOKUP($D11,'Medicine outputs'!$B:$AM,6,0)),"") -> rituximab | F11: =IFERROR(IF(VLOOKUP($D11,'Medicine outputs'!$B:$AM,8,0)=0,"",VLOOKUP($D11,'Medicine outputs'!$B:$AM,8,0)),"") -> Lymphoma, Non-Hodgkin;Arthritis, Rheumatoid;Leukemia, Lymphocytic, Chronic, B-Cell | G11: =IFERROR(IF(VLOOKUP($D11,'Medicine outputs'!$B:$AM,13,0)=0,"",VLOOKUP($D11,'Medicine outputs'!$B:$AM,13,0)),"") -> Antineoplastic agents | H11: =IFERROR(IF(VLOOKUP($D11,'Medicine outputs'!$B:$AM,11,0)=0,"",VLOOKUP($D11,'Medicine outputs'!$B:$AM,11,0)),"") -> L01XC02 | I11: NA | J11: =IF(OR(LEFT(H11,3)="L01",LEFT(H11,3)="L02",LEFT(I11,3)="L01",LEFT(I11,3)="L02"),"Yes","No") -> Yes | K11: https://www.ema.europa.eu/en/documents/variation-report/mabthera-h-c-165-ii-0162-epar-assessment-report-variation_en.pdf | L11: EMEA/H/C/000165/II/0162 | M11: MabThera, in combination with glucocorticoids, is indicated for the induction of remission in paediatric patients (aged ≥2 to <18 years old) with severe, active GPA (Wegener’s) and MPA. | N11: No | O11: NA | P11: =IF(OR(J11="No",N11="No",O11="Yes",Q11<>"NA"),"No","Yes") -> No | Q11: Indications other than onco-hematology | R11: NA | S11: NA | T11: NA | U11: NA
A12: 43831 | B12: https://www.ema.europa.eu/en/news/meeting-highlights-committee-medicinal-products-human-use-chmp-27-30-january-2020 | C12: Extensions of indications | D12: Rezolsta | E12: =IFERROR(IF(VLOOKUP($D12,'Medicine outputs'!$B:$AM,6,0)=0,"",VLOOKUP($D12,'Medicine outputs'!$B:$AM,6,0)),"") -> darunavir;cobicistat | F12: =IFERROR(IF(VLOOKUP($D12,'Medicine outputs'!$B:$AM,8,0)=0,"",VLOOKUP($D12,'Medicine outputs'!$B:$AM,8,0)),"") -> HIV Infections | G12: =IFERROR(IF(VLOOKUP($D12,'Medicine outputs'!$B:$AM,13,0)=0,"",VLOOKUP($D12,'Medicine outputs'!$B:$AM,13,0)),"") -> Antivirals for systemic use;Antivirals for treatment of HIV infections, combinations | H12: =IFERROR(IF(VLOOKUP($D12,'Medicine outputs'!$B:$AM,11,0)=0,"",VLOOKUP($D12,'Medicine outputs'!$B:$AM,11,0)),"") -> J05 | I12: NA | J12: =IF(OR(LEFT(H12,3)="L01",LEFT(H12,3)="L02",LEFT(I12,3)="L01",LEFT(I12,3)="L02"),"Yes","No") -> No | K12: NA | L12: NA | M12: NA | N12: NA | O12: NA | P12: =IF(OR(J12="No",N12="No",O12="Yes",Q12<>"NA"),"No","Yes") -> No | Q12: ATC code other than L01|L02 | R12: NA | S12: NA | T12: NA | U12: NA
A13: 43831 | B13: https://www.ema.europa.eu/en/news/meeting-highlights-committee-medicinal-products-human-use-chmp-27-30-january-2020 | C13: Extensions of indications | D13: Suliqua | E13: =IFERROR(IF(VLOOKUP($D13,'Medicine outputs'!$B:$AM,6,0)=0,"",VLOOKUP($D13,'Medicine outputs'!$B:$AM,6,0)),"") -> insulin glargine;lixisenatide | F13: =IFERROR(IF(VLOOKUP($D13,'Medicine outputs'!$B:$AM,8,0)=0,"",VLOOKUP($D13,'Medicine outputs'!$B:$AM,8,0)),"") -> Diabetes Mellitus, Type 2 | G13: =IFERROR(IF(VLOOKUP($D13,'Medicine outputs'!$B:$AM,13,0)=0,"",VLOOKUP($D13,'Medicine outputs'!$B:$AM,13,0)),"") -> Drugs used in diabetes | H13: =IFERROR(IF(VLOOKUP($D13,'Medicine outputs'!$B:$AM,11,0)=0,"",VLOOKUP($D13,'Medicine outputs'!$B:$AM,11,0)),"") -> A10AE54 | I13: NA | J13: =IF(OR(LEFT(H13,3)="L01",LEFT(H13,3)="L02",LEFT(I13,3)="L01",LEFT(I13,3)="L02"),"Yes","No") -> No | K13: NA | L13: NA | M13: NA | N13: NA | O13: NA | P13: =IF(OR(J13="No",N13="No",O13="Yes",Q13<>"NA"),"No","Yes") -> No | Q13: ATC code other than L01|L02 | R13: NA | S13: NA | T13: NA | U13: NA
A14: 43831 | B14: https://www.ema.europa.eu/en/news/meeting-highlights-committee-medicinal-products-human-use-chmp-27-30-january-2020 | C14: Extensions of indications | D14: Tybost | E14: =IFERROR(IF(VLOOKUP($D14,'Medicine outputs'!$B:$AM,6,0)=0,"",VLOOKUP($D14,'Medicine outputs'!$B:$AM,6,0)),"") -> cobicistat | F14: =IFERROR(IF(VLOOKUP($D14,'Medicine outputs'!$B:$AM,8,0)=0,"",VLOOKUP($D14,'Medicine outputs'!$B:$AM,8,0)),"") -> HIV Infections | G14: =IFERROR(IF(VLOOKUP($D14,'Medicine outputs'!$B:$AM,13,0)=0,"",VLOOKUP($D14,'Medicine outputs'!$B:$AM,13,0)),"") -> Antivirals for systemic use | H14: =IFERROR(IF(VLOOKUP($D14,'Medicine outputs'!$B:$AM,11,0)=0,"",VLOOKUP($D14,'Medicine outputs'!$B:$AM,11,0)),"") -> V03AX03 | I14: NA | J14: =IF(OR(LEFT(H14,3)="L01",LEFT(H14,3)="L02",LEFT(I14,3)="L01",LEFT(I14,3)="L02"),"Yes","No") -> No | K14: NA | L14: NA | M14: NA | N14: NA | O14: NA | P14: =IF(OR(J14="No",N14="No",O14="Yes",Q14<>"NA"),"No","Yes") -> No | Q14: ATC code other than L01|L02 | R14: NA | S14: NA | T14: NA | U14: NA
A15: 43831 | B15: https://www.ema.europa.eu/en/news/meeting-highlights-committee-medicinal-products-human-use-chmp-27-30-january-2020 | C15: Extensions of indications | D15: Venclyxto | E15: =IFERROR(IF(VLOOKUP($D15,'Medicine outputs'!$B:$AM,6,0)=0,"",VLOOKUP($D15,'Medicine outputs'!$B:$AM,6,0)),"") -> venetoclax | F15: =IFERROR(IF(VLOOKUP($D15,'Medicine outputs'!$B:$AM,8,0)=0,"",VLOOKUP($D15,'Medicine outputs'!$B:$AM,8,0)),"") -> Leukemia, Lymphocytic, Chronic, B-Cell | G15: =IFERROR(IF(VLOOKUP($D15,'Medicine outputs'!$B:$AM,13,0)=0,"",VLOOKUP($D15,'Medicine outputs'!$B:$AM,13,0)),"") -> Antineoplastic agents | H15: =IFERROR(IF(VLOOKUP($D15,'Medicine outputs'!$B:$AM,11,0)=0,"",VLOOKUP($D15,'Medicine outputs'!$B:$AM,11,0)),"") -> L01XX52 | I15: NA | J15: =IF(OR(LEFT(H15,3)="L01",LEFT(H15,3)="L02",LEFT(I15,3)="L01",LEFT(I15,3)="L02"),"Yes","No") -> Yes | K15: https://www.ema.europa.eu/en/documents/variation-report/venclyxto-h-c-4106-ii-0023-g-epar-assessment-report-variation_en.pdf | L15: EMEA/H/C/004106/II/0023/G | M15: Venclyxto in combination with obinutuzumab is indicated for the treatment of adult patients with previously untreated chronic lymphocytic leukaemia | N15: Yes | O15: No | P15: =IF(OR(J15="No",N15="No",O15="Yes",Q15<>"NA"),"No","Yes") -> Yes | Q15: NA | R15: 1 | S15: BO25323/CLL14 | T15: NCT02242942 | U15: NA
A16: 43862 | B16: https://www.ema.europa.eu/en/news/meeting-highlights-committee-medicinal-products-human-use-chmp-24-27-february-2020 | C16: New medicines | D16: Fetcroja | E16: =IFERROR(IF(VLOOKUP($D16,'Medicine outputs'!$B:$AM,6,0)=0,"",VLOOKUP($D16,'Medicine outputs'!$B:$AM,6,0)),"") -> cefiderocol | F16: =IFERROR(IF(VLOOKUP($D16,'Medicine outputs'!$B:$AM,8,0)=0,"",VLOOKUP($D16,'Medicine outputs'!$B:$AM,8,0)),"") -> Gram-Negative Bacterial Infections | G16: =IFERROR(IF(VLOOKUP($D16,'Medicine outputs'!$B:$AM,13,0)=0,"",VLOOKUP($D16,'Medicine outputs'!$B:$AM,13,0)),"") -> Antibacterials for systemic use | H16: =IFERROR(IF(VLOOKUP($D16,'Medicine outputs'!$B:$AM,11,0)=0,"",VLOOKUP($D16,'Medicine outputs'!$B:$AM,11,0)),"") -> J01D | I16: NA | J16: =IF(OR(LEFT(H16,3)="L01",LEFT(H16,3)="L02",LEFT(I16,3)="L01",LEFT(I16,3)="L02"),"Yes","No") -> No | K16: NA | L16: NA | M16: NA | N16: NA | O16: NA | P16: =IF(OR(J16="No",N16="No",O16="Yes",Q16<>"NA"),"No","Yes") -> No | Q16: ATC code other than L01|L02 | R16: NA | S16: NA | T16: NA | U16: NA
A17: 43862 | B17: https://www.ema.europa.eu/en/news/meeting-highlights-committee-medicinal-products-human-use-chmp-24-27-february-2020 | C17: Extensions of indications | D17: Alunbrig | E17: =IFERROR(IF(VLOOKUP($D17,'Medicine outputs'!$B:$AM,6,0)=0,"",VLOOKUP($D17,'Medicine outputs'!$B:$AM,6,0)),"") -> brigatinib | F17: =IFERROR(IF(VLOOKUP($D17,'Medicine outputs'!$B:$AM,8,0)=0,"",VLOOKUP($D17,'Medicine outputs'!$B:$AM,8,0)),"") -> Carcinoma, Non-Small-Cell Lung | G17: =IFERROR(IF(VLOOKUP($D17,'Medicine outputs'!$B:$AM,13,0)=0,"",VLOOKUP($D17,'Medicine outputs'!$B:$AM,13,0)),"") -> Antineoplastic agents | H17: =IFERROR(IF(VLOOKUP($D17,'Medicine outputs'!$B:$AM,11,0)=0,"",VLOOKUP($D17,'Medicine outputs'!$B:$AM,11,0)),"") -> L01XE43 | I17: NA | J17: =IF(OR(LEFT(H17,3)="L01",LEFT(H17,3)="L02",LEFT(I17,3)="L01",LEFT(I17,3)="L02"),"Yes","No") -> Yes | K17: https://www.ema.europa.eu/en/documents/variation-report/alunbrig-h-c-4248-ii-0003-epar-assessment-report-variation_en.pdf | L17: EMEA/H/C/004248/II/0003 | M17: Alunbrig is indicated as monotherapy for the treatment of adult patients with anaplastic lymphoma kinase (ALK) positive advanced non small cell lung cancer (NSCLC) previously not treated with an ALK inhibitor. | N17: Yes | O17: No | P17: =IF(OR(J17="No",N17="No",O17="Yes",Q17<>"NA"),"No","Yes") -> Yes | Q17: NA | R17: 1 | S17: AP26113-13-301 | T17: NCT02737501 | U17: NA
A18: 43862 | B18: https://www.ema.europa.eu/en/news/meeting-highlights-committee-medicinal-products-human-use-chmp-24-27-february-2020 | C18: Extensions of indications | D18: Ofev | E18: =IFERROR(IF(VLOOKUP($D18,'Medicine outputs'!$B:$AM,6,0)=0,"",VLOOKUP($D18,'Medicine outputs'!$B:$AM,6,0)),"") -> nintedanib | F18: =IFERROR(IF(VLOOKUP($D18,'Medicine outputs'!$B:$AM,8,0)=0,"",VLOOKUP($D18,'Medicine outputs'!$B:$AM,8,0)),"") -> Idiopathic Pulmonary Fibrosis | G18: =IFERROR(IF(VLOOKUP($D18,'Medicine outputs'!$B:$AM,13,0)=0,"",VLOOKUP($D18,'Medicine outputs'!$B:$AM,13,0)),"") -> Antineoplastic agents | H18: =IFERROR(IF(VLOOKUP($D18,'Medicine outputs'!$B:$AM,11,0)=0,"",VLOOKUP($D18,'Medicine outputs'!$B:$AM,11,0)),"") -> L01EX09 | I18: NA | J18: =IF(OR(LEFT(H18,3)="L01",LEFT(H18,3)="L02",LEFT(I18,3)="L01",LEFT(I18,3)="L02"),"Yes","No") -> Yes | K18: https://www.ema.europa.eu/en/documents/variation-report/ofev-h-c-003821-ii-0026-epar-assessment-report-variation_en.pdf | L18: EMEA/H/C/003821/II/0026 | M18: Extension of Indication to include new indication for OFEV for the treatment of Systemic Sclerosis associated Interstitial Lung Disease | N18: No | O18: NA | P18: =IF(OR(J18="No",N18="No",O18="Yes",Q18<>"NA"),"No","Yes") -> No | Q18: Indications other than onco-hematology | R18: NA | S18: NA | T18: NA | U18: NA
A19: 43862 | B19: https://www.ema.europa.eu/en/news/meeting-highlights-committee-medicinal-products-human-use-chmp-24-27-february-2020 | C19: Extensions of indications | D19: Otezla | E19: =IFERROR(IF(VLOOKUP($D19,'Medicine outputs'!$B:$AM,6,0)=0,"",VLOOKUP($D19,'Medicine outputs'!$B:$AM,6,0)),"") -> apremilast | F19: =IFERROR(IF(VLOOKUP($D19,'Medicine outputs'!$B:$AM,8,0)=0,"",VLOOKUP($D19,'Medicine outputs'!$B:$AM,8,0)),"") -> Arthritis, Psoriatic;Psoriasis;Behcet Syndrome | G19: =IFERROR(IF(VLOOKUP($D19,'Medicine outputs'!$B:$AM,13,0)=0,"",VLOOKUP($D19,'Medicine outputs'!$B:$AM,13,0)),"") -> Immunosuppressants | H19: =IFERROR(IF(VLOOKUP($D19,'Medicine outputs'!$B:$AM,11,0)=0,"",VLOOKUP($D19,'Medicine outputs'!$B:$AM,11,0)),"") -> L04AA32 | I19: NA | J19: =IF(OR(LEFT(H19,3)="L01",LEFT(H19,3)="L02",LEFT(I19,3)="L01",LEFT(I19,3)="L02"),"Yes","No") -> No | K19: NA | L19: NA | M19: NA | N19: NA | O19: NA | P19: =IF(OR(J19="No",N19="No",O19="Yes",Q19<>"NA"),"No","Yes") -> No | Q19: ATC code other than L01|L02 | R19: NA | S19: NA | T19: NA | U19: NA
A20: 43891 | B20: https://www.ema.europa.eu/en/news/meeting-highlights-committee-medicinal-products-human-use-chmp-23-26-march-2020-updated | C20: New medicines | D20: Atectura Breezhaler | E20: =IFERROR(IF(VLOOKUP($D20,'Medicine outputs'!$B:$AM,6,0)=0,"",VLOOKUP($D20,'Medicine outputs'!$B:$AM,6,0)),"") -> indacaterol;mometasone | F20: =IFERROR(IF(VLOOKUP($D20,'Medicine outputs'!$B:$AM,8,0)=0,"",VLOOKUP($D20,'Medicine outputs'!$B:$AM,8,0)),"") -> Asthma | G20: =IFERROR(IF(VLOOKUP($D20,'Medicine outputs'!$B:$AM,13,0)=0,"",VLOOKUP($D20,'Medicine outputs'!$B:$AM,13,0)),"") -> Drugs for obstructive airway diseases | H20: =IFERROR(IF(VLOOKUP($D20,'Medicine outputs'!$B:$AM,11,0)=0,"",VLOOKUP($D20,'Medicine outputs'!$B:$AM,11,0)),"") -> R03AK | I20: NA | J20: =IF(OR(LEFT(H20,3)="L01",LEFT(H20,3)="L02",LEFT(I20,3)="L01",LEFT(I20,3)="L02"),"Yes","No") -> No | K20: NA | L20: NA | M20: NA | N20: NA | O20: NA | P20: =IF(OR(J20="No",N20="No",O20="Yes",Q20<>"NA"),"No","Yes") -> No | Q20: ATC code other than L01|L02 | R20: NA | S20: NA | T20: NA | U20: NA
A21: 43891 | B21: https://www.ema.europa.eu/en/news/meeting-highlights-committee-medicinal-products-human-use-chmp-23-26-march-2020-updated | C21: New medicines | D21: Bemrist Breezhaler | E21: =IFERROR(IF(VLOOKUP($D21,'Medicine outputs'!$B:$AM,6,0)=0,"",VLOOKUP($D21,'Medicine outputs'!$B:$AM,6,0)),"") -> indacaterol;mometasone | F21: =IFERROR(IF(VLOOKUP($D21,'Medicine outputs'!$B:$AM,8,0)=0,"",VLOOKUP($D21,'Medicine outputs'!$B:$AM,8,0)),"") -> Asthma | G21: =IFERROR(IF(VLOOKUP($D21,'Medicine outputs'!$B:$AM,13,0)=0,"",VLOOKUP($D21,'Medicine outputs'!$B:$AM,13,0)),"") -> Drugs for obstructive airway diseases | H21: =IFERROR(IF(VLOOKUP($D21,'Medicine outputs'!$B:$AM,11,0)=0,"",VLOOKUP($D21,'Medicine outputs'!$B:$AM,11,0)),"") -> R03AK | I21: NA | J21: =IF(OR(LEFT(H21,3)="L01",LEFT(H21,3)="L02",LEFT(I21,3)="L01",LEFT(I21,3)="L02"),"Yes","No") -> No | K21: NA | L21: NA | M21: NA | N21: NA | O21: NA | P21: =IF(OR(J21="No",N21="No",O21="Yes",Q21<>"NA"),"No","Yes") -> No | Q21: ATC code other than L01|L02 | R21: NA | S21: NA | T21: NA | U21: NA
A22: 43891 | B22: https://www.ema.europa.eu/en/news/meeting-highlights-committee-medicinal-products-human-use-chmp-23-26-march-2020-updated | C22: New medicines | D22: Dovprela (previously Pretomanid FGK) | E22: =IFERROR(IF(VLOOKUP($D22,'Medicine outputs'!$B:$AM,6,0)=0,"",VLOOKUP($D22,'Medicine outputs'!$B:$AM,6,0)),"") -> pretomanid | F22: =IFERROR(IF(VLOOKUP($D22,'Medicine outputs'!$B:$AM,8,0)=0,"",VLOOKUP($D22,'Medicine outputs'!$B:$AM,8,0)),"") -> Tuberculosis, Multidrug-Resistant | G22: =IFERROR(IF(VLOOKUP($D22,'Medicine outputs'!$B:$AM,13,0)=0,"",VLOOKUP($D22,'Medicine outputs'!$B:$AM,13,0)),"") -> Antimycobacterials | H22: =IFERROR(IF(VLOOKUP($D22,'Medicine outputs'!$B:$AM,11,0)=0,"",VLOOKUP($D22,'Medicine outputs'!$B:$AM,11,0)),"") -> J04 | I22: NA | J22: =IF(OR(LEFT(H22,3)="L01",LEFT(H22,3)="L02",LEFT(I22,3)="L01",LEFT(I22,3)="L02"),"Yes","No") -> No | K22: NA | L22: NA | M22: NA | N22: NA | O22: NA | P22: =IF(OR(J22="No",N22="No",O22="Yes",Q22<>"NA"),"No","Yes") -> No | Q22: ATC code other than L01|L02 | R22: NA | S22: NA | T22: NA | U22: NA
A23: 43891 | B23: https://www.ema.europa.eu/en/news/meeting-highlights-committee-medicinal-products-human-use-chmp-23-26-march-2020-updated | C23: New medicines | D23: Fluad Tetra | E23: =IFERROR(IF(VLOOKUP($D23,'Medicine outputs'!$B:$AM,6,0)=0,"",VLOOKUP($D23,'Medicine outputs'!$B:$AM,6,0)),"") -> influenza vaccine (surface antigen, inactivated, adjuvanted) | F23: =IFERROR(IF(VLOOKUP($D23,'Medicine outputs'!$B:$AM,8,0)=0,"",VLOOKUP($D23,'Medicine outputs'!$B:$AM,8,0)),"") -> Influenza, Human | G23: =IFERROR(IF(VLOOKUP($D23,'Medicine outputs'!$B:$AM,13,0)=0,"",VLOOKUP($D23,'Medicine outputs'!$B:$AM,13,0)),"") -> Vaccines | H23: =IFERROR(IF(VLOOKUP($D23,'Medicine outputs'!$B:$AM,11,0)=0,"",VLOOKUP($D23,'Medicine outputs'!$B:$AM,11,0)),"") -> J07BB02 | I23: NA | J23: =IF(OR(LEFT(H23,3)="L01",LEFT(H23,3)="L02",LEFT(I23,3)="L01",LEFT(I23,3)="L02"),"Yes","No") -> No | K23: NA | L23: NA | M23: NA | N23: NA | O23: NA | P23: =IF(OR(J23="No",N23="No",O23="Yes",Q23<>"NA"),"No","Yes") -> No | Q23: ATC code other than L01|L02 | R23: NA | S23: NA | T23: NA | U23: NA
A24: 43891 | B24: https://www.ema.europa.eu/en/news/meeting-highlights-committee-medicinal-products-human-use-chmp-23-26-march-2020-updated | C24: New medicines | D24: Sarclisa | E24: =IFERROR(IF(VLOOKUP($D24,'Medicine outputs'!$B:$AM,6,0)=0,"",VLOOKUP($D24,'Medicine outputs'!$B:$AM,6,0)),"") -> isatuximab | F24: =IFERROR(IF(VLOOKUP($D24,'Medicine outputs'!$B:$AM,8,0)=0,"",VLOOKUP($D24,'Medicine outputs'!$B:$AM,8,0)),"") -> Multiple Myeloma | G24: =IFERROR(IF(VLOOKUP($D24,'Medicine outputs'!$B:$AM,13,0)=0,"",VLOOKUP($D24,'Medicine outputs'!$B:$AM,13,0)),"") -> Antineoplastic agents | H24: =IFERROR(IF(VLOOKUP($D24,'Medicine outputs'!$B:$AM,11,0)=0,"",VLOOKUP($D24,'Medicine outputs'!$B:$AM,11,0)),"") -> L01XC38 | I24: NA | J24: =IF(OR(LEFT(H24,3)="L01",LEFT(H24,3)="L02",LEFT(I24,3)="L01",LEFT(I24,3)="L02"),"Yes","No") -> Yes | K24: https://www.ema.europa.eu/en/documents/assessment-report/sarclisa-epar-public-assessment-report_en.pdf | L24: EMEA/H/C/004977/0000 | M24: Sarclisa is indicated, in combination with pomalidomide and dexamethasone, for the treatment of adult patients with relapsed and refractory multiple myeloma (MM) who have received at least two prior therapies including lenalidomide and a proteasome inhibitor (PI) and have demonstrated disease progression on the last therapy. | N24: Yes | O24: No | P24: =IF(OR(J24="No",N24="No",O24="Yes",Q24<>"NA"),"No","Yes") -> Yes | Q24: NA | R24: 1 | S24: EFC14335/ICARIA | T24: NCT02990338 | U24: NA
A25: 43891 | B25: https://www.ema.europa.eu/en/news/meeting-highlights-committee-medicinal-products-human-use-chmp-23-26-march-2020-updated | C25: New medicines | D25: Zeposia | E25: =IFERROR(IF(VLOOKUP($D25,'Medicine outputs'!$B:$AM,6,0)=0,"",VLOOKUP($D25,'Medicine outputs'!$B:$AM,6,0)),"") -> ozanimod | F25: =IFERROR(IF(VLOOKUP($D25,'Medicine outputs'!$B:$AM,8,0)=0,"",VLOOKUP($D25,'Medicine outputs'!$B:$AM,8,0)),"") -> Multiple Sclerosis, Relapsing-Remitting;Colitis, Ulcerative | G25: =IFERROR(IF(VLOOKUP($D25,'Medicine outputs'!$B:$AM,13,0)=0,"",VLOOKUP($D25,'Medicine outputs'!$B:$AM,13,0)),"") -> Immunosuppressants | H25: =IFERROR(IF(VLOOKUP($D25,'Medicine outputs'!$B:$AM,11,0)=0,"",VLOOKUP($D25,'Medicine outputs'!$B:$AM,11,0)),"") -> L04AA38 | I25: NA | J25: =IF(OR(LEFT(H25,3)="L01",LEFT(H25,3)="L02",LEFT(I25,3)="L01",LEFT(I25,3)="L02"),"Yes","No") -> No | K25: NA | L25: NA | M25: NA | N25: NA | O25: NA | P25: =IF(OR(J25="No",N25="No",O25="Yes",Q25<>"NA"),"No","Yes") -> No | Q25: ATC code other than L01|L02 | R25: NA | S25: NA | T25: NA | U25: NA
A26: 43891 | B26: https://www.ema.europa.eu/en/news/meeting-highlights-committee-medicinal-products-human-use-chmp-23-26-march-2020-updated | C26: New medicines | D26: Zolgensma | E26: =IFERROR(IF(VLOOKUP($D26,'Medicine outputs'!$B:$AM,6,0)=0,"",VLOOKUP($D26,'Medicine outputs'!$B:$AM,6,0)),"") -> onasemnogene abeparvovec | F26: =IFERROR(IF(VLOOKUP($D26,'Medicine outputs'!$B:$AM,8,0)=0,"",VLOOKUP($D26,'Medicine outputs'!$B:$AM,8,0)),"") -> Muscular Atrophy, Spinal | G26: =IFERROR(IF(VLOOKUP($D26,'Medicine outputs'!$B:$AM,13,0)=0,"",VLOOKUP($D26,'Medicine outputs'!$B:$AM,13,0)),"") -> Other drugs for disorders of the musculo-skeletal system | H26: =IFERROR(IF(VLOOKUP($D26,'Medicine outputs'!$B:$AM,11,0)=0,"",VLOOKUP($D26,'Medicine outputs'!$B:$AM,11,0)),"") -> M09AX09 | I26: NA | J26: =IF(OR(LEFT(H26,3)="L01",LEFT(H26,3)="L02",LEFT(I26,3)="L01",LEFT(I26,3)="L02"),"Yes","No") -> No | K26: NA | L26: NA | M26: NA | N26: NA | O26: NA | P26: =IF(OR(J26="No",N26="No",O26="Yes",Q26<>"NA"),"No","Yes") -> No | Q26: ATC code other than L01|L02 | R26: NA | S26: NA | T26: NA | U26: NA
A27: 43891 | B27: https://www.ema.europa.eu/en/news/meeting-highlights-committee-medicinal-products-human-use-chmp-23-26-march-2020-updated | C27: Extensions of indications | D27: Adcetris | E27: =IFERROR(IF(VLOOKUP($D27,'Medicine outputs'!$B:$AM,6,0)=0,"",VLOOKUP($D27,'Medicine outputs'!$B:$AM,6,0)),"") -> brentuximab vedotin | F27: =IFERROR(IF(VLOOKUP($D27,'Medicine outputs'!$B:$AM,8,0)=0,"",VLOOKUP($D27,'Medicine outputs'!$B:$AM,8,0)),"") -> Lymphoma, Non-Hodgkin;Hodgkin Disease | G27: =IFERROR(IF(VLOOKUP($D27,'Medicine outputs'!$B:$AM,13,0)=0,"",VLOOKUP($D27,'Medicine outputs'!$B:$AM,13,0)),"") -> Antineoplastic agents | H27: =IFERROR(IF(VLOOKUP($D27,'Medicine outputs'!$B:$AM,11,0)=0,"",VLOOKUP($D27,'Medicine outputs'!$B:$AM,11,0)),"") -> L01XC12 | I27: NA | J27: =IF(OR(LEFT(H27,3)="L01",LEFT(H27,3)="L02",LEFT(I27,3)="L01",LEFT(I27,3)="L02"),"Yes","No") -> Yes | K27: https://www.ema.europa.eu/en/documents/variation-report/adcetris-h-c-002455-ii-0070-epar-assessment-report-variation_en.pdf | L27: EMEA/H/C/002455/II/0070 | M27: Extension of indications to include in combination with cyclophosphamide, doxorubicin, and prednisone | N27: Yes | O27: No | P27: =IF(OR(J27="No",N27="No",O27="Yes",Q27<>"NA"),"No","Yes") -> Yes | Q27: NA | R27: 1 | S27: ECHELON-2 (SGN35-014) | T27: NCT01777152 | U27: NA
A28: 43891 | B28: https://www.ema.europa.eu/en/news/meeting-highlights-committee-medicinal-products-human-use-chmp-23-26-march-2020-updated | C28: Extensions of indications | D28: Cosentyx | E28: =IFERROR(IF(VLOOKUP($D28,'Medicine outputs'!$B:$AM,6,0)=0,"",VLOOKUP($D28,'Medicine outputs'!$B:$AM,6,0)),"") -> secukinumab | F28: =IFERROR(IF(VLOOKUP($D28,'Medicine outputs'!$B:$AM,8,0)=0,"",VLOOKUP($D28,'Medicine outputs'!$B:$AM,8,0)),"") -> Arthritis, Psoriatic;Psoriasis;Spondylitis, Ankylosing | G28: =IFERROR(IF(VLOOKUP($D28,'Medicine outputs'!$B:$AM,13,0)=0,"",VLOOKUP($D28,'Medicine outputs'!$B:$AM,13,0)),"") -> Immunosuppressants | H28: =IFERROR(IF(VLOOKUP($D28,'Medicine outputs'!$B:$AM,11,0)=0,"",VLOOKUP($D28,'Medicine outputs'!$B:$AM,11,0)),"") -> L04AC10 | I28: NA | J28: =IF(OR(LEFT(H28,3)="L01",LEFT(H28,3)="L02",LEFT(I28,3)="L01",LEFT(I28,3)="L02"),"Yes","No") -> No | K28: NA | L28: NA | M28: NA | N28: NA | O28: NA | P28: =IF(OR(J28="No",N28="No",O28="Yes",Q28<>"NA"),"No","Yes") -> No | Q28: ATC code other than L01|L02 | R28: NA | S28: NA | T28: NA | U28: NA
A29: 43891 | B29: https://www.ema.europa.eu/en/news/meeting-highlights-committee-medicinal-products-human-use-chmp-23-26-march-2020-updated | C29: Extensions of indications | D29: Intelence | E29: =IFERROR(IF(VLOOKUP($D29,'Medicine outputs'!$B:$AM,6,0)=0,"",VLOOKUP($D29,'Medicine outputs'!$B:$AM,6,0)),"") -> etravirine | F29: =IFERROR(IF(VLOOKUP($D29,'Medicine outputs'!$B:$AM,8,0)=0,"",VLOOKUP($D29,'Medicine outputs'!$B:$AM,8,0)),"") -> HIV Infections | G29: =IFERROR(IF(VLOOKUP($D29,'Medicine outputs'!$B:$AM,13,0)=0,"",VLOOKUP($D29,'Medicine outputs'!$B:$AM,13,0)),"") -> Non-nucleoside reverse transcriptase inhibitors;Antivirals for systemic use | H29: =IFERROR(IF(VLOOKUP($D29,'Medicine outputs'!$B:$AM,11,0)=0,"",VLOOKUP($D29,'Medicine outputs'!$B:$AM,11,0)),"") -> J05AG04 | I29: NA | J29: =IF(OR(LEFT(H29,3)="L01",LEFT(H29,3)="L02",LEFT(I29,3)="L01",LEFT(I29,3)="L02"),"Yes","No") -> No | K29: NA | L29: NA | M29: NA | N29: NA | O29: NA | P29: =IF(OR(J29="No",N29="No",O29="Yes",Q29<>"NA"),"No","Yes") -> No | Q29: ATC code other than L01|L02 | R29: NA | S29: NA | T29: NA | U29: NA
A30: 43891 | B30: https://www.ema.europa.eu/en/news/meeting-highlights-committee-medicinal-products-human-use-chmp-23-26-march-2020-updated | C30: Extensions of indications | D30: Jorveza | E30: =IFERROR(IF(VLOOKUP($D30,'Medicine outputs'!$B:$AM,6,0)=0,"",VLOOKUP($D30,'Medicine outputs'!$B:$AM,6,0)),"") -> budesonide | F30: =IFERROR(IF(VLOOKUP($D30,'Medicine outputs'!$B:$AM,8,0)=0,"",VLOOKUP($D30,'Medicine outputs'!$B:$AM,8,0)),"") -> Esophageal Diseases | G30: =IFERROR(IF(VLOOKUP($D30,'Medicine outputs'!$B:$AM,13,0)=0,"",VLOOKUP($D30,'Medicine outputs'!$B:$AM,13,0)),"") -> Antidiarrheals, intestinal antiinflammatory / antiinfective agents | H30: =IFERROR(IF(VLOOKUP($D30,'Medicine outputs'!$B:$AM,11,0)=0,"",VLOOKUP($D30,'Medicine outputs'!$B:$AM,11,0)),"") -> A07EA06 | I30: NA | J30: =IF(OR(LEFT(H30,3)="L01",LEFT(H30,3)="L02",LEFT(I30,3)="L01",LEFT(I30,3)="L02"),"Yes","No") -> No | K30: NA | L30: NA | M30: NA | N30: NA | O30: NA | P30: =IF(OR(J30="No",N30="No",O30="Yes",Q30<>"NA"),"No","Yes") -> No | Q30: ATC code other than L01|L02 | R30: NA | S30: NA | T30: NA | U30: NA
A31: 43891 | B31: https://www.ema.europa.eu/en/news/meeting-highlights-committee-medicinal-products-human-use-chmp-23-26-march-2020-updated | C31: Extensions of indications | D31: Kineret | E31: =IFERROR(IF(VLOOKUP($D31,'Medicine outputs'!$B:$AM,6,0)=0,"",VLOOKUP($D31,'Medicine outputs'!$B:$AM,6,0)),"") -> anakinra | F31: =IFERROR(IF(VLOOKUP($D31,'Medicine outputs'!$B:$AM,8,0)=0,"",VLOOKUP($D31,'Medicine outputs'!$B:$AM,8,0)),"") -> Arthritis, Rheumatoid;COVID-19 virus infection | G31: =IFERROR(IF(VLOOKUP($D31,'Medicine outputs'!$B:$AM,13,0)=0,"",VLOOKUP($D31,'Medicine outputs'!$B:$AM,13,0)),"") -> Immunosuppressants | H31: =IFERROR(IF(VLOOKUP($D31,'Medicine outputs'!$B:$AM,11,0)=0,"",VLOOKUP($D31,'Medicine outputs'!$B:$AM,11,0)),"") -> L04AC03 | I31: NA | J31: =IF(OR(LEFT(H31,3)="L01",LEFT(H31,3)="L02",LEFT(I31,3)="L01",LEFT(I31,3)="L02"),"Yes","No") -> No | K31: NA | L31: NA | M31: NA | N31: NA | O31: NA | P31: =IF(OR(J31="No",N31="No",O31="Yes",Q31<>"NA"),"No","Yes") -> No | Q31: ATC code other than L01|L02 | R31: NA | S31: NA | T31: NA | U31: NA
A32: 43891 | B32: https://www.ema.europa.eu/en/news/meeting-highlights-committee-medicinal-products-human-use-chmp-23-26-march-2020-updated | C32: Extensions of indications | D32: Ruconest | E32: =IFERROR(IF(VLOOKUP($D32,'Medicine outputs'!$B:$AM,6,0)=0,"",VLOOKUP($D32,'Medicine outputs'!$B:$AM,6,0)),"") -> conestat alfa | F32: =IFERROR(IF(VLOOKUP($D32,'Medicine outputs'!$B:$AM,8,0)=0,"",VLOOKUP($D32,'Medicine outputs'!$B:$AM,8,0)),"") -> Angioedemas, Hereditary | G32: =IFERROR(IF(VLOOKUP($D32,'Medicine outputs'!$B:$AM,13,0)=0,"",VLOOKUP($D32,'Medicine outputs'!$B:$AM,13,0)),"") -> Drugs used in hereditary angioedema;Other hematological agents | H32: =IFERROR(IF(VLOOKUP($D32,'Medicine outputs'!$B:$AM,11,0)=0,"",VLOOKUP($D32,'Medicine outputs'!$B:$AM,11,0)),"") -> B06AC04 | I32: NA | J32: =IF(OR(LEFT(H32,3)="L01",LEFT(H32,3)="L02",LEFT(I32,3)="L01",LEFT(I32,3)="L02"),"Yes","No") -> No | K32: NA | L32: NA | M32: NA | N32: NA | O32: NA | P32: =IF(OR(J32="No",N32="No",O32="Yes",Q32<>"NA"),"No","Yes") -> No | Q32: ATC code other than L01|L02 | R32: NA | S32: NA | T32: NA | U32: NA
A33: 43922 | B33: https://www.ema.europa.eu/en/news/meeting-highlights-committee-medicinal-products-human-use-chmp-28-30-april-2020 | C33: New medicines | D33: Daurismo | E33: =IFERROR(IF(VLOOKUP($D33,'Medicine outputs'!$B:$AM,6,0)=0,"",VLOOKUP($D33,'Medicine outputs'!$B:$AM,6,0)),"") -> glasdegib | F33: =IFERROR(IF(VLOOKUP($D33,'Medicine outputs'!$B:$AM,8,0)=0,"",VLOOKUP($D33,'Medicine outputs'!$B:$AM,8,0)),"") -> Leukemia, Myeloid, Acute | G33: =IFERROR(IF(VLOOKUP($D33,'Medicine outputs'!$B:$AM,13,0)=0,"",VLOOKUP($D33,'Medicine outputs'!$B:$AM,13,0)),"") -> Antineoplastic agents | H33: =IFERROR(IF(VLOOKUP($D33,'Medicine outputs'!$B:$AM,11,0)=0,"",VLOOKUP($D33,'Medicine outputs'!$B:$AM,11,0)),"") -> L01XX63 | I33: NA | J33: =IF(OR(LEFT(H33,3)="L01",LEFT(H33,3)="L02",LEFT(I33,3)="L01",LEFT(I33,3)="L02"),"Yes","No") -> Yes | K33: https://www.ema.europa.eu/en/documents/assessment-report/daurismo-epar-public-assessment-report_en.pdf | L33: EMEA/H/C/004878/0000 | M33: Daurismo is indicated, in combination with low-dose cytarabine, for the treatment of newly diagnosed de novo or secondary acute myeloid leukaemia (AML) in adult patients who are not candidates for standard induction chemotherapy | N33: Yes | O33: No | P33: =IF(OR(J33="No",N33="No",O33="Yes",Q33<>"NA"),"No","Yes") -> Yes | Q33: NA | R33: 1 | S33: B1371003 | T33: NCT01546038 | U33: NA
A34: 43922 | B34: https://www.ema.europa.eu/en/news/meeting-highlights-committee-medicinal-products-human-use-chmp-28-30-april-2020 | C34: New medicines | D34: Enerzair Breezhaler | E34: =IFERROR(IF(VLOOKUP($D34,'Medicine outputs'!$B:$AM,6,0)=0,"",VLOOKUP($D34,'Medicine outputs'!$B:$AM,6,0)),"") -> indacaterol;glycopyrronium bromide;mometasone | F34: =IFERROR(IF(VLOOKUP($D34,'Medicine outputs'!$B:$AM,8,0)=0,"",VLOOKUP($D34,'Medicine outputs'!$B:$AM,8,0)),"") -> Asthma | G34: =IFERROR(IF(VLOOKUP($D34,'Medicine outputs'!$B:$AM,13,0)=0,"",VLOOKUP($D34,'Medicine outputs'!$B:$AM,13,0)),"") -> Drugs for obstructive airway diseases | H34: =IFERROR(IF(VLOOKUP($D34,'Medicine outputs'!$B:$AM,11,0)=0,"",VLOOKUP($D34,'Medicine outputs'!$B:$AM,11,0)),"") -> R03AL | I34: NA | J34: =IF(OR(LEFT(H34,3)="L01",LEFT(H34,3)="L02",LEFT(I34,3)="L01",LEFT(I34,3)="L02"),"Yes","No") -> No | K34: NA | L34: NA | M34: NA | N34: NA | O34: NA | P34: =IF(OR(J34="No",N34="No",O34="Yes",Q34<>"NA"),"No","Yes") -> No | Q34: ATC code other than L01|L02 | R34: NA | S34: NA | T34: NA | U34: NA
A35: 43922 | B35: https://www.ema.europa.eu/en/news/meeting-highlights-committee-medicinal-products-human-use-chmp-28-30-april-2020 | C35: New medicines | D35: Reblozyl | E35: =IFERROR(IF(VLOOKUP($D35,'Medicine outputs'!$B:$AM,6,0)=0,"",VLOOKUP($D35,'Medicine outputs'!$B:$AM,6,0)),"") -> luspatercept | F35: =IFERROR(IF(VLOOKUP($D35,'Medicine outputs'!$B:$AM,8,0)=0,"",VLOOKUP($D35,'Medicine outputs'!$B:$AM,8,0)),"") -> Anemia;Myelodysplastic Syndromes;beta-Thalassemia | G35: =IFERROR(IF(VLOOKUP($D35,'Medicine outputs'!$B:$AM,13,0)=0,"",VLOOKUP($D35,'Medicine outputs'!$B:$AM,13,0)),"") -> Other antianemic preparations | H35: =IFERROR(IF(VLOOKUP($D35,'Medicine outputs'!$B:$AM,11,0)=0,"",VLOOKUP($D35,'Medicine outputs'!$B:$AM,11,0)),"") -> B03XA06 | I35: NA | J35: =IF(OR(LEFT(H35,3)="L01",LEFT(H35,3)="L02",LEFT(I35,3)="L01",LEFT(I35,3)="L02"),"Yes","No") -> No | K35: NA | L35: NA | M35: NA | N35: NA | O35: NA | P35: =IF(OR(J35="No",N35="No",O35="Yes",Q35<>"NA"),"No","Yes") -> No | Q35: ATC code other than L01|L02 | R35: NA | S35: NA | T35: NA | U35: NA
A36: 43922 | B36: https://www.ema.europa.eu/en/news/meeting-highlights-committee-medicinal-products-human-use-chmp-28-30-april-2020 | C36: New medicines | D36: Zimbus Breezhaler | E36: =IFERROR(IF(VLOOKUP($D36,'Medicine outputs'!$B:$AM,6,0)=0,"",VLOOKUP($D36,'Medicine outputs'!$B:$AM,6,0)),"") -> indacaterol;glycopyrronium;mometasone furoate | F36: =IFERROR(IF(VLOOKUP($D36,'Medicine outputs'!$B:$AM,8,0)=0,"",VLOOKUP($D36,'Medicine outputs'!$B:$AM,8,0)),"") -> Asthma | G36: =IFERROR(IF(VLOOKUP($D36,'Medicine outputs'!$B:$AM,13,0)=0,"",VLOOKUP($D36,'Medicine outputs'!$B:$AM,13,0)),"") -> Drugs for obstructive airway diseases | H36: =IFERROR(IF(VLOOKUP($D36,'Medicine outputs'!$B:$AM,11,0)=0,"",VLOOKUP($D36,'Medicine outputs'!$B:$AM,11,0)),"") -> R03AL | I36: NA | J36: =IF(OR(LEFT(H36,3)="L01",LEFT(H36,3)="L02",LEFT(I36,3)="L01",LEFT(I36,3)="L02"),"Yes","No") -> No | K36: NA | L36: NA | M36: NA | N36: NA | O36: NA | P36: =IF(OR(J36="No",N36="No",O36="Yes",Q36<>"NA"),"No","Yes") -> No | Q36: ATC code other than L01|L02 | R36: NA | S36: NA | T36: NA | U36: NA
A37: 43922 | B37: https://www.ema.europa.eu/en/news/meeting-highlights-committee-medicinal-products-human-use-chmp-28-30-april-2020 | C37: Extensions of indications | D37: Braftovi | E37: =IFERROR(IF(VLOOKUP($D37,'Medicine outputs'!$B:$AM,6,0)=0,"",VLOOKUP($D37,'Medicine outputs'!$B:$AM,6,0)),"") -> encorafenib | F37: =IFERROR(IF(VLOOKUP($D37,'Medicine outputs'!$B:$AM,8,0)=0,"",VLOOKUP($D37,'Medicine outputs'!$B:$AM,8,0)),"") -> Melanoma;Colorectal Neoplasms | G37: =IFERROR(IF(VLOOKUP($D37,'Medicine outputs'!$B:$AM,13,0)=0,"",VLOOKUP($D37,'Medicine outputs'!$B:$AM,13,0)),"") -> Antineoplastic agents | H37: =IFERROR(IF(VLOOKUP($D37,'Medicine outputs'!$B:$AM,11,0)=0,"",VLOOKUP($D37,'Medicine outputs'!$B:$AM,11,0)),"") -> L01EC03 | I37: NA | J37: =IF(OR(LEFT(H37,3)="L01",LEFT(H37,3)="L02",LEFT(I37,3)="L01",LEFT(I37,3)="L02"),"Yes","No") -> Yes | K37: https://www.ema.europa.eu/en/documents/variation-report/braftovi-h-c-4280-ws-1695-epar-assessment-report-variation_en.pdf | L37: EMEA/H/C/xxxx/WS/1695 | M37: Extension of indicationsto include in combination with cetuximab, for the treatment of adult patients with metastatic colorectal cancer (CRC) with a BRAF V600E mutation, who have received prior systemic therapy. | N37: Yes | O37: No | P37: =IF(OR(J37="No",N37="No",O37="Yes",Q37<>"NA"),"No","Yes") -> Yes | Q37: NA | R37: 1 | S37: BEACON CRC Study (ARRAY-818-302) | T37: NCT02928224 | U37: NA
A38: 43922 | B38: https://www.ema.europa.eu/en/news/meeting-highlights-committee-medicinal-products-human-use-chmp-28-30-april-2020 | C38: Extensions of indications | D38: Cablivi | E38: =IFERROR(IF(VLOOKUP($D38,'Medicine outputs'!$B:$AM,6,0)=0,"",VLOOKUP($D38,'Medicine outputs'!$B:$AM,6,0)),"") -> caplacizumab | F38: =IFERROR(IF(VLOOKUP($D38,'Medicine outputs'!$B:$AM,8,0)=0,"",VLOOKUP($D38,'Medicine outputs'!$B:$AM,8,0)),"") -> Purpura, Thrombotic Thrombocytopenic | G38: =IFERROR(IF(VLOOKUP($D38,'Medicine outputs'!$B:$AM,13,0)=0,"",VLOOKUP($D38,'Medicine outputs'!$B:$AM,13,0)),"") -> Antithrombotic agents | H38: =IFERROR(IF(VLOOKUP($D38,'Medicine outputs'!$B:$AM,11,0)=0,"",VLOOKUP($D38,'Medicine outputs'!$B:$AM,11,0)),"") -> B01A | I38: NA | J38: =IF(OR(LEFT(H38,3)="L01",LEFT(H38,3)="L02",LEFT(I38,3)="L01",LEFT(I38,3)="L02"),"Yes","No") -> No | K38: NA | L38: NA | M38: NA | N38: NA | O38: NA | P38: =IF(OR(J38="No",N38="No",O38="Yes",Q38<>"NA"),"No","Yes") -> No | Q38: ATC code other than L01|L02 | R38: NA | S38: NA | T38: NA | U38: NA
A39: 43922 | B39: https://www.ema.europa.eu/en/news/meeting-highlights-committee-medicinal-products-human-use-chmp-28-30-april-2020 | C39: Extensions of indications | D39: Carmustine medac (previously Carmustine Obvius) | E39: =IFERROR(IF(VLOOKUP($D39,'Medicine outputs'!$B:$AM,6,0)=0,"",VLOOKUP($D39,'Medicine outputs'!$B:$AM,6,0)),"") -> carmustine | F39: =IFERROR(IF(VLOOKUP($D39,'Medicine outputs'!$B:$AM,8,0)=0,"",VLOOKUP($D39,'Medicine outputs'!$B:$AM,8,0)),"") -> Hodgkin Disease;Lymphoma, Non-Hodgkin | G39: =IFERROR(IF(VLOOKUP($D39,'Medicine outputs'!$B:$AM,13,0)=0,"",VLOOKUP($D39,'Medicine outputs'!$B:$AM,13,0)),"") -> Antineoplastic agents | H39: =IFERROR(IF(VLOOKUP($D39,'Medicine outputs'!$B:$AM,11,0)=0,"",VLOOKUP($D39,'Medicine outputs'!$B:$AM,11,0)),"") -> L01AD01 | I39: NA | J39: =IF(OR(LEFT(H39,3)="L01",LEFT(H39,3)="L02",LEFT(I39,3)="L01",LEFT(I39,3)="L02"),"Yes","No") -> Yes | K39: https://www.ema.europa.eu/en/documents/variation-report/carmustine-obvius-h-c-4326-ii-0002-epar-assessment-report-variation_en.pdf | L39: EMEA/H/C/004326/II/0002 | M39: Extension of indicationsto include as conditioning treatment prior to autologous haematopoietic progenitor cell transplantation (HPCT) in malignant haematological diseases (Hodgkin’s disease / Non-hodgkin’s lymphoma). | N39: Yes | O39: No | P39: =IF(OR(J39="No",N39="No",O39="Yes",Q39<>"NA"),"No","Yes") -> No | Q39: No RCT | R39: 0 | S39: NA | T39: NA | U39: NA
A40: 43922 | B40: https://www.ema.europa.eu/en/news/meeting-highlights-committee-medicinal-products-human-use-chmp-28-30-april-2020 | C40: Extensions of indications | D40: Ecalta | E40: =IFERROR(IF(VLOOKUP($D40,'Medicine outputs'!$B:$AM,6,0)=0,"",VLOOKUP($D40,'Medicine outputs'!$B:$AM,6,0)),"") -> anidulafungin | F40: =IFERROR(IF(VLOOKUP($D40,'Medicine outputs'!$B:$AM,8,0)=0,"",VLOOKUP($D40,'Medicine outputs'!$B:$AM,8,0)),"") -> Candidiasis | G40: =IFERROR(IF(VLOOKUP($D40,'Medicine outputs'!$B:$AM,13,0)=0,"",VLOOKUP($D40,'Medicine outputs'!$B:$AM,13,0)),"") -> Antimycotics for systemic use | H40: =IFERROR(IF(VLOOKUP($D40,'Medicine outputs'!$B:$AM,11,0)=0,"",VLOOKUP($D40,'Medicine outputs'!$B:$AM,11,0)),"") -> J02AX06 | I40: NA | J40: =IF(OR(LEFT(H40,3)="L01",LEFT(H40,3)="L02",LEFT(I40,3)="L01",LEFT(I40,3)="L02"),"Yes","No") -> No | K40: NA | L40: NA | M40: NA | N40: NA | O40: NA | P40: =IF(OR(J40="No",N40="No",O40="Yes",Q40<>"NA"),"No","Yes") -> No | Q40: ATC code other than L01|L02 | R40: NA | S40: NA | T40: NA | U40: NA
...

Sheet Medicine outputs
A1: Content type: | B1: Medicine | C1: Output automatically generated from content on www.ema.europa.eu on: | D1: 26/03/2025 - 18:00
A9: Category | B9: Name of medicine | C9: EMA product number | D9: Medicine status | E9: Opinion status | F9: Latest procedure affecting product information | G9: International non-proprietary name (INN) / common name | H9: Active substance | I9: Therapeutic area (MeSH) | J9: Species (veterinary) | K9: Patient safety | L9: ATC code (human) | M9: ATCvet code (veterinary) | N9: Pharmacotherapeutic group (human) | O9: Pharmacotherapeutic group (veterinary) | P9: Therapeutic indication | Q9: Accelerated assessment | R9: Additional monitoring | S9: Advanced therapy | T9: Biosimilar | U9: Conditional approval | V9: Exceptional circumstances | W9: Generic or hybrid | X9: Orphan medicine | Y9: PRIME: priority medicine | Z9: Marketing authorisation developer / applicant / holder | AA9: European Commission decision date | AB9: Start of rolling review date | AC9: Start of evaluation date | AD9: Opinion adopted date | AE9: Withdrawal of application date | AF9: Marketing authorisation date | AG9: Refusal of marketing authorisation date | AH9: Withdrawal / expiry / revocation / lapse of marketing authorisation date | AI9: Suspension of marketing authorisation date | AJ9: Revision number | AK9: First published date | AL9: Last updated date | AM9: Medicine URL
A10: Human | B10: Korjuny | C10: EMEA/H/C/005697 | D10: Authorised | F10: VR/0000255947 | G10: catumaxomab | H10: catumaxomab | I10: Ascites | K10: No | L10: L01FX03 | N10: Antineoplastic agents | P10: Korjuny is indicated for the intraperitoneal treatment of malignant ascites in adults with epithelial cellular adhesion molecule (EpCAM)-positive carcinomas, who are not eligible for further systemic anticancer therapy. | Q10: No | R10: No | S10: No | T10: No | U10: No | V10: No | W10: No | X10: No | Y10: No | Z10: Lindis Biotech GmbH | AA10: 26/03/2025 | AD10: 17/10/2024 | AF10: 10/02/2025 | AJ10: 1 | AK10: 18/10/2024 | AL10: 26/03/2025 | AM10: https://www.ema.europa.eu/en/medicines/human/EPAR/korjuny
A11: Human | B11: Vegzelma | C11: EMEA/H/C/005534 | D11: Authorised | F11: VR/0000258086 | G11: bevacizumab | H11: bevacizumab | I11: Colorectal Neoplasms;Breast Neoplasms;Ovarian Neoplasms;Fallopian Tube Neoplasms;Peritoneal Neoplasms;Carcinoma, Non-Small-Cell Lung;Carcinoma, Renal Cell;Uterine Cervical Neoplasms | K11: No | L11: L01XC07 | N11: Antineoplastic agents | P11: VEGZELMA in combination with fluoropyrimidine based chemotherapy is indicated for treatment of adult patients with metastatic carcinoma of the colon or rectum. VEGZELMA in combination with paclitaxel is indicated for first line treatment of adult patients with metastatic breast cancer. For further information as to human epidermal growth factor receptor 2 (HER2) status, please refer to section 5.1. VEGZELMA in combination with capecitabine is indicated for first line treatment of adult patients with metastatic breast cancer in whom treatment with other chemotherapy options including taxanes or anthracyclines is not considered appropriate. Patients who have received taxane and anthracycline containing regimens in the adjuvant setting within the last 12 months should be excluded from treatment with VEGZELMA in combination with capecitabine. For further information as to HER2 status, please refer to section 5.1. VEGZELMA, in addition to platinum based chemotherapy, is indicated for first line treatment of adult patients with unresectable advanced, metastatic or recurrent non small cell lung cancer (NSCLC) other than predominantly squamous cell histology. VEGZELMA, in combination with erlotinib, is indicated for first line treatment of adult patients with unresectable advanced, metastatic or recurrent NSCLC with Epidermal Growth Factor Receptor (EGFR) activating mutations (see section 5.1). VEGZELMA, in combination with interferon alfa 2a is indicated for first line treatment of adult patients with advanced and/or metastatic renal cell cancer. VEGZELMA, in combination with carboplatin and paclitaxel is indicated for the front line treatment of adult patients with advanced (International Federation of Gynecology and Obstetrics (FIGO) stages III B, III C and IV) epithelial ovarian, fallopian tube, or primary peritoneal cancer (see section 5.1). VEGZELMA, in combination with carboplatin and gemcitabine or in combination with carboplatin and paclitaxel, is indicated for treatment of adult patients with first recurrence of platinum sensitive epithelial ovarian, fallopian tube or primary peritoneal cancer who have not received prior therapy with bevacizumab or other vascular endothelial growth factor (VEGF) inhibitors or VEGF receptor–targeted agents. VEGZELMA in combination with paclitaxel, topotecan, or pegylated liposomal doxorubicin is indicated for the treatment of adult patients with platinum resistant recurrent epithelial ovarian, fallopian tube, or primary peritoneal cancer who received no more than two prior chemotherapy regimens and who have not received prior therapy with bevacizumab or other VEGF inhibitors or VEGF receptor–targeted agents (see section 5.1). VEGZELMA, in combination with paclitaxel and cisplatin or, alternatively, paclitaxel and topotecan in patients who cannot receive platinum therapy, is indicated for the treatment of adult patients with persistent, recurrent, or metastatic carcinoma of the cervix (see section 5.1). | Q11: No | R11: Yes | S11: No | T11: Yes | U11: No | V11: No | W11: No | X11: No | Y11: No | Z11: Celltrion Healthcare Hungary Kft. | AA11: 26/03/2025 | AD11: 23/06/2022 | AF11: 17/08/2022 | AJ11: 10 | AK11: 20/06/2022 | AL11: 26/03/2025 | AM11: https://www.ema.europa.eu/en/medicines/human/EPAR/vegzelma
A12: Human | B12: Cosentyx | C12: EMEA/H/C/003729 | D12: Authorised | F12: II/0127 | G12: secukinumab | H12: Secukinumab | I12: Arthritis, Psoriatic;Psoriasis;Spondylitis, Ankylosing | K12: No | L12: L04AC10 | N12: Immunosuppressants | P12: Plaque psoriasis Cosentyx is indicated for the treatment of moderate to severe plaque psoriasis in adults and children from the age of 6 years old who are candidates for systemic therapy. Hidradenitis suppurativa (HS) Cosentyx is indicated for the treatment of active moderate to severe hidradenitis suppurativa (acne inversa) in adults with an inadequate response to conventional systemic HS therapy. Psoriatic arthritis Cosentyx, alone or in combination with methotrexate (MTX), is indicated for the treatment of active psoriatic arthritis in adult patients when the response to previous disease modifying anti rheumatic drug (DMARD) therapy has been inadequate. Axial spondyloarthritis (axSpA) Ankylosing spondylitis (AS, radiographic axial spondyloarthritis) Cosentyx is indicated for the treatment of active ankylosing spondylitis in adults who have responded inadequately to conventional therapy. Non-radiographic axial spondyloarthritis (nr-axSpA) Cosentyx is indicated for the treatment of active non-radiographic axial spondyloarthritis with objective signs of inflammation as indicated by elevated C-reactive protein (CRP) and/or magnetic resonance imaging (MRI) evidence in adults who have responded inadequately to non steroidal anti inflammatory drugs (NSAIDs). Juvenile idiopathic arthritis (JIA) Enthesitis-related arthritis (ERA) Cosentyx, alone or in combination with methotrexate (MTX), is indicated for the treatment of active enthesitis-related arthritis in patients 6 years and older whose disease has responded inadequately to, or who cannot tolerate, conventional therapy. Juvenile psoriatic arthritis (JPsA) Cosentyx, alone or in combination with methotrexate (MTX), is indicated for the treatment of active juvenile psoriatic arthritis in patients 6 years and older whose disease has responded inadequately to, or who cannot tolerate, conventional therapy. | Q12: No | R12: No | S12: No | T12: No | U12: No | V12: No | W12: No | X12: No | Y12: No | Z12: Novartis Europharm Limited | AA12: 13/02/2025 | AD12: 20/11/2014 | AF12: 14/01/2015 | AJ12: 40 | AK12: 07/06/2018 | AL12: 26/03/2025 | AM12: https://www.ema.europa.eu/en/medicines/human/EPAR/cosentyx
A13: Human | B13: Columvi | C13: EMEA/H/C/005751 | D13: Authorised | F13: VR/0000249350 | G13: glofitamab | H13: Glofitamab | I13: Lymphoma, Large B-Cell, Diffuse | K13: No | L13: L01FX28 | N13: Antineoplastic agents | P13: Columvi as monotherapy is indicated for the treatment of adult patients with relapsed or refractory diffuse large B cell lymphoma (DLBCL), after two or more lines of systemic therapy. | Q13: No | R13: Yes | S13: No | T13: No | U13: Yes | V13: No | W13: No | X13: Yes | Y13: No | Z13: Roche Registration GmbH | AA13: 26/03/2025 | AD13: 26/04/2023 | AF13: 07/07/2023 | AJ13: 4 | AK13: 18/07/2023 | AL13: 26/03/2025 | AM13: https://www.ema.europa.eu/en/medicines/human/EPAR/columvi
A14: Human | B14: Kadcyla | C14: EMEA/H/C/002389 | D14: Authorised | F14: II/0071/G | G14: trastuzumab emtansine | H14: trastuzumab emtansine | I14: Breast Neoplasms | K14: No | L14: L01XC14 | N14: Antineoplastic agents | P14: Early Breast Cancer (EBC) Kadcyla, as a single agent, is indicated for the adjuvant treatment of adult patients with HER2-positive early breast cancer who have residual invasive disease, in the breast and/or lymph nodes, after neoadjuvant taxane-based and HER2-targeted therapy. Metastatic Breast Cancer (MBC) Kadcyla, as a single agent, is indicated for the treatment of adult patients with HER2-positive, unresectable locally advanced or metastatic breast cancer who previously received trastuzumab and a taxane, separately or in combination. Patients should have either: Received prior therapy for locally advanced or metastatic disease, or Developed disease recurrence during or within six months of completing adjuvant therapy. | Q14: No | R14: No | S14: No | T14: No | U14: No | V14: No | W14: No | X14: No | Y14: No | Z14: Roche Registration GmbH | AA14: 20/02/2025 | AD14: 19/09/2013 | AF14: 15/11/2013 | AJ14: 16 | AK14: 19/12/2013 | AL14: 26/03/2025 | AM14: https://www.ema.europa.eu/en/medicines/human/EPAR/kadcyla
A15: Human | B15: Lopinavir/Ritonavir Viatris (previously Ritonavir Mylan) | C15: EMEA/H/C/004025 | D15: Authorised | F15: N/0000256687 | G15: lopinavir;ritonavir | H15: lopinavir;ritonavir | I15: HIV Infections | K15: No | L15: J05AR10 | N15: Antivirals for systemic use | P15: Lopinavir/ritonavir is indicated in combination with other antiretroviral medicinal products for the treatment of human immunodeficiency virus (HIV-1) infected adults, adolescents and children above the age of 2 years. The choice of lopinavir/ritonavir to treat protease inhibitor experienced HIV-1 infected patients should be based on individual viral resistance testing and treatment history of patients. | Q15: No | R15: No | S15: No | T15: No | U15: No | V15: No | W15: Yes | X15: No | Y15: No | Z15: Viatris Limited | AA15: 26/03/2025 | AD15: 19/11/2015 | AF15: 14/01/2016 | AJ15: 21 | AK15: 14/06/2018 | AL15: 26/03/2025 | AM15: https://www.ema.europa.eu/en/medicines/human/EPAR/lopinavir-ritonavir-viatris
A16: Human | B16: Uplizna | C16: EMEA/H/C/005818 | D16: Authorised | F16: IAIN/0013 | G16: inebilizumab | H16: Inebilizumab | I16: Neuromyelitis Optica | K16: No | L16: L04AA | N16: Immunosuppressants | P16: Uplizna is indicated as monotherapy for the treatment of adult patients with neuromyelitis optica spectrum disorders (NMOSD) who are anti-aquaporin 4 immunoglobulin G (AQP4-IgG) seropositive (see section 5.1). | Q16: No | R16: Yes | S16: No | T16: No | U16: No | V16: No | W16: No | X16: No | Y16: No | Z16: Horizon Therapeutics Ireland DAC | AA16: 13/01/2025 | AD16: 11/11/2021 | AF16: 25/04/2022 | AJ16: 5 | AK16: 11/11/2021 | AL16: 26/03/2025 | AM16: https://www.ema.europa.eu/en/medicines/human/EPAR/uplizna
A17: Human | B17: Nimvastid | C17: EMEA/H/C/001029 | D17: Authorised | F17: VR/0000253876 | G17: rivastigmine | H17: rivastigmine | I17: Dementia;Alzheimer Disease;Parkinson Disease | K17: No | L17: N06DA03 | N17: Psychoanaleptics | P17: Symptomatic treatment of mild to moderately severe Alzheimer's dementia. Symptomatic treatment of mild to moderately severe dementia in patients with idiopathic Parkinson's disease. | Q17: No | R17: No | S17: No | T17: No | U17: No | V17: No | W17: Yes | X17: No | Y17: No | Z17: Krka, d.d., Novo mesto | AA17: 26/03/2025 | AF17: 11/05/2009 | AJ17: 12 | AK17: 18/01/2018 | AL17: 26/03/2025 | AM17: https://www.ema.europa.eu/en/medicines/human/EPAR/nimvastid
A18: Human | B18: Samsca | C18: EMEA/H/C/000980 | D18: Authorised | F18: II/0051 | G18: tolvaptan | H18: Tolvaptan | I18: Inappropriate ADH Syndrome | K18: No | L18: C03XA01 | N18: Diuretics | P18: Treatment of adult patients with hyponatraemia secondary to syndrome of inappropriate antidiuretic-hormone secretion (SIADH). | Q18: No | R18: No | S18: No | T18: No | U18: No | V18: No | W18: No | X18: No | Y18: No | Z18: Otsuka Pharmaceutical Netherlands B.V. | AA18: 13/02/2025 | AD18: 28/05/2009 | AF18: 02/08/2009 | AJ18: 16 | AK18: 29/06/2018 | AL18: 26/03/2025 | AM18: https://www.ema.europa.eu/en/medicines/human/EPAR/samsca
A19: Human | B19: Xenpozyme | C19: EMEA/H/C/004850 | D19: Authorised | F19: II/0013/G | G19: olipudase alfa | H19: Olipudase alfa | I19: Acid sphingomyelinase deficiency (ASMD) type A/B or type B | K19: No | L19: A16AB25 | N19: Other alimentary tract and metabolism products | P19: Xenpozyme is indicated as an enzyme replacement therapy for the treatment of non-Central Nervous System (CNS) manifestations of Acid Sphingomyelinase Deficiency (ASMD) in paediatric and adult patients with type A/B or type B. | Q19: No | R19: Yes | S19: No | T19: No | U19: No | V19: No | W19: No | X19: Yes | Y19: Yes | Z19: Sanofi B.V. | AA19: 13/02/2025 | AD19: 19/05/2022 | AF19: 24/06/2022 | AJ19: 6 | AK19: 20/05/2022 | AL19: 26/03/2025 | AM19: https://www.ema.europa.eu/en/medicines/human/EPAR/xenpozyme
